<?xml version='1.3'?>
<sdf version='1.6'>
  <model name='tarot_650'>
    <static>false</static>
     
  <!-- LINKS -->
    <link name='base_link'>
      <pose>0 0 0 0 0 0</pose>
      
      <inertial>
        <pose>0 0 0 0 0 0</pose>
        <mass>2.620</mass>
        <inertia>
          <ixx>0.042467</ixx>
          <iyy>0.043367</iyy>
          <izz>0.063267</izz>
          
          <ixy>0</ixy>
          <ixz>0</ixz>
          <iyz>0</iyz>
        </inertia>
      </inertial>
      
      <collision name='base_link_inertia_collision'>
        <pose>0 0 -0.03 0 -0 0</pose>
        <geometry>
          <box>
            <size>0.4796194077712559 0.4796194077712559 0.33</size>
          </box>
        </geometry>
        <surface>
          <contact>
            <ode>
              <min_depth>0.001</min_depth>
              <max_vel>0</max_vel>
            </ode>
          </contact>
          <friction>
            <ode/>
          </friction>
        </surface>
      </collision>
      <visual name='base_link_inertia_visual'>
        <pose>0.241 0.241 -0.2 0 0 3.141590</pose>
        <geometry>
          <mesh>
            <uri>model://tarot_650/meshes/TarotGazebo.STL</uri>
            <scale>0.001 0.001 0.001</scale>
          </mesh>
        </geometry>
        <material>
          <script>
            <name>Gazebo/DarkGrey</name>
            <uri>__default__</uri>
          </script>
        </material>
      </visual>
      <gravity>1</gravity>
      <velocity_decay/>
    </link>


    <link name="rotor_0">
     <gravity>1</gravity>
      <velocity_decay/>
      <pose>0.22 -0.22 0.05 0 0 0</pose>
      <inertial>
          <mass>0.019</mass>
          <inertia>
            <ixx>6.349166666666668e-07</ixx>
            <iyy>4.310783333333334e-05</iyy>
            <izz>4.373958333333334e-05</izz>
          </inertia>
        </inertial>
      <visual name="rotor_0_visual">
        <pose>-0.1905 0.02523 -0.01 1.571 0 0</pose>
        <geometry>
          <mesh>
            <scale>0.001 0.001 0.001</scale>
            <uri>model://tarot_650/meshes/TarotProp.STL</uri>
          </mesh>
        </geometry>
        <material>
          <script>
            <name>Gazebo/Blue</name>
            <uri>file://media/materials/scripts/gazebo.material</uri>
          </script>
        </material>
      </visual>
    </link>

    <link name="rotor_1">
     <gravity>1</gravity>
      <velocity_decay/>
      <pose>-0.22 0.22 0.05 0 0 0</pose>
      <inertial>
          <mass>0.019</mass>
          <inertia>
            <ixx>6.349166666666668e-07</ixx>
            <iyy>4.310783333333334e-05</iyy>
            <izz>4.373958333333334e-05</izz>
          </inertia>
        </inertial>
      <visual name="rotor_1_visual">
        <pose>-0.1905 0.02523 -0.01 1.571 0 0</pose>
        <geometry>
          <mesh>
            <scale>0.001 0.001 0.001</scale>
            <uri>model://tarot_650/meshes/TarotProp.STL</uri>
          </mesh>
        </geometry>
        <material>
          <script>
            <name>Gazebo/Blue</name>
            <uri>file://media/materials/scripts/gazebo.material</uri>
          </script>
        </material>
      </visual>
    </link>

    <link name="rotor_2">
     <gravity>1</gravity>
      <velocity_decay/>
      <pose>0.22 0.22 0.05 0 0 0</pose>
      <inertial>
          <mass>0.019</mass>
          <inertia>
            <ixx>6.349166666666668e-07</ixx>
            <iyy>4.310783333333334e-05</iyy>
            <izz>4.373958333333334e-05</izz>
          </inertia>
        </inertial>
      <visual name="rotor_2_visual">
        <pose>-0.1905 0.02523 -0.01 1.571 0 0</pose>
        <geometry>
          <mesh>
            <scale>0.001 0.001 0.001</scale>
            <uri>model://tarot_650/meshes/TarotProp.STL</uri>
          </mesh>
        </geometry>
        <material>
          <script>
            <name>Gazebo/Blue</name>
            <uri>file://media/materials/scripts/gazebo.material</uri>
          </script>
        </material>
      </visual>
    </link>

    <link name="rotor_3">
     <gravity>1</gravity>
      <velocity_decay/>
      <pose>-0.22 -0.22 0.05 0 0 0</pose>
      <inertial>
          <mass>0.019</mass>
          <inertia>
            <ixx>6.349166666666668e-07</ixx>
            <iyy>4.310783333333334e-05</iyy>
            <izz>4.373958333333334e-05</izz>
          </inertia>
        </inertial>
      <visual name="rotor_3_visual">
        <pose>-0.1905 0.02523 -0.01 1.571 0 0</pose>
        <geometry>
          <mesh>
            <scale>0.001 0.001 0.001</scale>
            <uri>model://tarot_650/meshes/TarotProp.STL</uri>
          </mesh>
        </geometry>
        <material>
          <script>
            <name>Gazebo/Blue</name>
            <uri>file://media/materials/scripts/gazebo.material</uri>
          </script>
        </material>
      </visual>
    </link>

<!-- JOINTS -->

    <joint name='/imu_joint' type='revolute'>
      <child>/imu_link</child>
      <parent>base_link</parent>
      <axis>
        <xyz>1 0 0</xyz>
        <limit>
          <lower>0</lower>
          <upper>0</upper>
          <effort>0</effort>
          <velocity>0</velocity>
        </limit>
        <dynamics>
          <spring_reference>0</spring_reference>
          <spring_stiffness>0</spring_stiffness>
        </dynamics>
        <use_parent_model_frame>1</use_parent_model_frame>
      </axis>
    </joint>


    <joint name='rotor_0_joint' type='revolute'>
      <child>rotor_0</child>
      <parent>base_link</parent>
      <axis>
        <xyz>0 0 1</xyz>
        <limit>
          <lower>-1e+16</lower>
          <upper>1e+16</upper>
        </limit>
        <dynamics>
          <spring_reference>0</spring_reference>
          <spring_stiffness>0</spring_stiffness>
        </dynamics>
        <use_parent_model_frame>1</use_parent_model_frame>
      </axis>
    </joint>


    <joint name='rotor_1_joint' type='revolute'>
      <child>rotor_1</child>
      <parent>base_link</parent>
      <axis>
        <xyz>0 0 1</xyz>
        <limit>
          <lower>-1e+16</lower>
          <upper>1e+16</upper>
        </limit>
        <dynamics>
          <spring_reference>0</spring_reference>
          <spring_stiffness>0</spring_stiffness>
        </dynamics>
        <use_parent_model_frame>1</use_parent_model_frame>
      </axis>
    </joint>


    <joint name='rotor_2_joint' type='revolute'>
      <child>rotor_2</child>
      <parent>base_link</parent>
      <axis>
        <xyz>0 0 1</xyz>
        <limit>
          <lower>-1e+16</lower>
          <upper>1e+16</upper>
        </limit>
        <dynamics>
          <spring_reference>0</spring_reference>
          <spring_stiffness>0</spring_stiffness>
        </dynamics>
        <use_parent_model_frame>1</use_parent_model_frame>
      </axis>
    </joint>


    <joint name='rotor_3_joint' type='revolute'>
      <child>rotor_3</child>
      <parent>base_link</parent>
      <axis>
        <xyz>0 0 1</xyz>
        <limit>
          <lower>-1e+16</lower>
          <upper>1e+16</upper>
        </limit>
        <dynamics>
          <spring_reference>0</spring_reference>
          <spring_stiffness>0</spring_stiffness>
        </dynamics>
        <use_parent_model_frame>1</use_parent_model_frame>
      </axis>
    </joint>


<!-- PLUGINS -->

    <plugin
      filename="libpx4_gz_sim.so"
      name="px4_interface">
    </plugin>

    <plugin name='front_right_motor_model' filename='libpx4_motor_model.so'>
      <robotNamespace/>
      <jointName>rotor_0_joint</jointName>
      <linkName>rotor_0</linkName>
      <motorNumber>0</motorNumber>
      
      <turningDirection>ccw</turningDirection>
      <maxRotVelocity>883</maxRotVelocity>
      <motorConstant>2.5911e-05</motorConstant>
      <momentConstant>0.0166605</momentConstant>
      
      <timeConstantUp>0.0125</timeConstantUp>
      <timeConstantDown>0.025</timeConstantDown>
      <rotorDragCoefficient>0.000806428</rotorDragCoefficient>
      <rollingMomentCoefficient>1e-06</rollingMomentCoefficient>
      <rotorVelocitySlowdownSim>10</rotorVelocitySlowdownSim>
    </plugin>


    <plugin name='back_left_motor_model' filename='libpx4_motor_model.so'>
      <robotNamespace/>
      <jointName>rotor_1_joint</jointName>
      <linkName>rotor_1</linkName>
      <motorNumber>1</motorNumber>
      
      <turningDirection>ccw</turningDirection>
      <maxRotVelocity>883</maxRotVelocity>
      <motorConstant>2.5911e-05</motorConstant>
      <momentConstant>0.0166605</momentConstant>
      
      <timeConstantUp>0.0125</timeConstantUp>
      <timeConstantDown>0.025</timeConstantDown>
      <rotorDragCoefficient>0.000806428</rotorDragCoefficient>
      <rollingMomentCoefficient>1e-06</rollingMomentCoefficient>
      <rotorVelocitySlowdownSim>10</rotorVelocitySlowdownSim>
    </plugin>


    <plugin name='front_left_motor_model' filename='libpx4_motor_model.so'>
      <robotNamespace/>
      <jointName>rotor_2_joint</jointName>
      <linkName>rotor_2</linkName>
      <motorNumber>2</motorNumber>
      
      <turningDirection>cw</turningDirection>
      <maxRotVelocity>883</maxRotVelocity>
      <motorConstant>2.5911e-05</motorConstant>
      <momentConstant>0.0166605</momentConstant>
      
      <timeConstantUp>0.0125</timeConstantUp>
      <timeConstantDown>0.025</timeConstantDown>
      <rotorDragCoefficient>0.000806428</rotorDragCoefficient>
      <rollingMomentCoefficient>1e-06</rollingMomentCoefficient>
      <rotorVelocitySlowdownSim>10</rotorVelocitySlowdownSim>
    </plugin>


    <plugin name='back_right_motor_model' filename='libpx4_motor_model.so'>
      <robotNamespace/>
      <jointName>rotor_3_joint</jointName>
      <linkName>rotor_3</linkName>
      <motorNumber>3</motorNumber>
      
      <turningDirection>cw</turningDirection>
      <maxRotVelocity>883</maxRotVelocity>
      <motorConstant>2.5911e-05</motorConstant>
      <momentConstant>0.0166605</momentConstant>

      <timeConstantUp>0.0125</timeConstantUp>
      <timeConstantDown>0.025</timeConstantDown>
      <rotorDragCoefficient>0.000806428</rotorDragCoefficient>
      <rollingMomentCoefficient>1e-06</rollingMomentCoefficient>
      <rotorVelocitySlowdownSim>10</rotorVelocitySlowdownSim>
    </plugin>

  </model>
</sdf>
